<?xml version="1.0" ?>
<!-- =================================================================================== -->
<!-- |    This document was autogenerated by xacro from model.xacro                    | -->
<!-- |    EDITING THIS FILE BY HAND IS NOT RECOMMENDED                                 | -->
<!-- =================================================================================== -->
<robot name="cherry">
  <link name="base_link">
    <visual>
      <geometry>
        <box size="1.5 1.0 0.2"/>
      </geometry>
      <material name="blue"/>
    </visual>
    <collision>
      <geometry>
        <box size="1.5 1.0  0.2"/>
      </geometry>
    </collision>
    <inertial>
      <origin rpy="0.0 0.0 0.0" xyz="0.0 0.0 0.0"/>
      <mass value="0.5"/>
      <geometry>
        <box size="1.5 1.0  0.2"/>
      </geometry>
    </inertial>
    <collision>
      <geometry>
        <box size="1.5 1.0  0.2"/>
      </geometry>
    </collision>
  </link>
  <!-- front right limb -->
  <link name="thigh_FR">
    <inertial>
      <origin rpy="1.5707963267948966 0 0 " xyz="0 0 -0.2"/>
      <mass value="0.1"/>
      <geometry>
        <box size="1.5 1.0  0.2"/>
      </geometry>
    </inertial>
    <visual name="">
      <origin rpy="1.5707963267948966 0 0 " xyz="0 0 -0.2"/>
      <geometry>
        <box size="0.1 0.5 0.03 "/>
      </geometry>
      <material name="">
        <color rgba="1.0 0.0 0.0 1.0"/>
        <texture filename=""/>
        <texture filename=""/>
      </material>
    </visual>
    <collision>
      <origin rpy="0.0 0.0 0.0" xyz="0.0 0.0 0.0"/>
      <geometry>
        <box size="0.1 0.5 0.03 "/>
      </geometry>
    </collision>
  </link>
  <link name="leg_FR">
    <inertial>
      <origin rpy="0.0 0.0 0.0" xyz="0.0 0.0 0.0"/>
      <mass value="0.0"/>
      <inertia ixx="0.0" ixy="0.0" ixz="0.0" iyy="0.0" iyz="0.0" izz="0.0"/>
    </inertial>
    <visual name="">
      <origin rpy="1.5707963267948966 0 0" xyz="0 0 -0.2"/>
      <geometry>
        <box size="0.1 0.5 0.03 "/>
      </geometry>
      <material name="">
        <color rgba="1.0 0.0 1.0 1.0"/>
        <texture filename=""/>
        <texture filename=""/>
      </material>
    </visual>
    <collision>
      <origin rpy="0.0 0.0 0.0" xyz="0.0 0.0 0.0"/>
      <geometry>
        <box size="0.1 0.5 0.03 "/>
      </geometry>
    </collision>
  </link>
  <!-- front right limb -->
  <link name="thigh_BR">
    <inertial>
      <origin rpy="0.0 0.0 0.0" xyz="0.0 0.0 0.0"/>
      <mass value="0.0"/>
      <inertia ixx="0.0" ixy="0.0" ixz="0.0" iyy="0.0" iyz="0.0" izz="0.0"/>
    </inertial>
    <visual name="">
      <origin rpy="1.5707963267948966 0 0 " xyz="0 0 -0.2"/>
      <geometry>
        <box size="0.1 0.5 0.03 "/>
      </geometry>
      <material name="">
        <color rgba="1.0 0.0 0.0 1.0"/>
        <texture filename=""/>
        <texture filename=""/>
      </material>
    </visual>
    <collision>
      <origin rpy="0.0 0.0 0.0" xyz="0.0 0.0 0.0"/>
      <geometry>
        <box size="0.1 0.5 0.03 "/>
      </geometry>
    </collision>
  </link>
  <link name="leg_BR">
    <inertial>
      <origin rpy="0.0 0.0 0.0" xyz="0.0 0.0 0.0"/>
      <mass value="0.0"/>
      <inertia ixx="0.0" ixy="0.0" ixz="0.0" iyy="0.0" iyz="0.0" izz="0.0"/>
    </inertial>
    <visual name="">
      <origin rpy="1.5707963267948966 0 0" xyz="0 0 -0.2"/>
      <geometry>
        <box size="0.1 0.5 0.03 "/>
      </geometry>
      <material name="">
        <color rgba="1.0 0.0 1.0 1.0"/>
        <texture filename=""/>
        <texture filename=""/>
      </material>
    </visual>
    <collision>
      <origin rpy="0.0 0.0 0.0" xyz="0.0 0.0 0.0"/>
      <geometry>
        <box size="0.1 0.5 0.03 "/>
      </geometry>
    </collision>
  </link>
  <!-- front left limb -->
  <link name="thigh_FL">
    <inertial>
      <origin rpy="0.0 0.0 0.0" xyz="0.0 0.0 0.0"/>
      <mass value="0.0"/>
      <inertia ixx="0.0" ixy="0.0" ixz="0.0" iyy="0.0" iyz="0.0" izz="0.0"/>
    </inertial>
    <visual name="">
      <origin rpy="1.5707963267948966 0 0 " xyz="0 0 -0.2"/>
      <geometry>
        <box size="0.1 0.5 0.03 "/>
      </geometry>
      <material name="">
        <color rgba="1.0 0.0 0.0 1.0"/>
        <texture filename=""/>
        <texture filename=""/>
      </material>
    </visual>
    <collision>
      <origin rpy="0.0 0.0 0.0" xyz="0.0 0.0 0.0"/>
      <geometry>
        <box size="0.1 0.5 0.03 "/>
      </geometry>
    </collision>
  </link>
  <link name="leg_FL">
    <inertial>
      <origin rpy="0.0 0.0 0.0" xyz="0.0 0.0 0.0"/>
      <mass value="0.0"/>
      <inertia ixx="0.0" ixy="0.0" ixz="0.0" iyy="0.0" iyz="0.0" izz="0.0"/>
    </inertial>
    <visual name="">
      <origin rpy="1.5707963267948966 0 0" xyz="0 0 -0.2"/>
      <geometry>
        <box size="0.1 0.5 0.03 "/>
      </geometry>
      <material name="">
        <color rgba="1.0 0.0 1.0 1.0"/>
        <texture filename=""/>
        <texture filename=""/>
      </material>
    </visual>
    <collision>
      <origin rpy="0.0 0.0 0.0" xyz="0.0 0.0 0.0"/>
      <geometry>
        <box size="0.1 0.5 0.03 "/>
      </geometry>
    </collision>
  </link>
  <!-- back left limb -->
  <link name="thigh_BL">
    <inertial>
      <origin rpy="0.0 0.0 0.0" xyz="0.0 0.0 0.0"/>
      <mass value="0.0"/>
      <inertia ixx="0.0" ixy="0.0" ixz="0.0" iyy="0.0" iyz="0.0" izz="0.0"/>
    </inertial>
    <visual name="">
      <origin rpy="1.5707963267948966 0 0 " xyz="0 0 -0.2"/>
      <geometry>
        <box size="0.1 0.5 0.03 "/>
      </geometry>
      <material name="">
        <color rgba="1.0 0.0 0.0 1.0"/>
        <texture filename=""/>
        <texture filename=""/>
      </material>
    </visual>
    <collision>
      <origin rpy="0.0 0.0 0.0" xyz="0.0 0.0 0.0"/>
      <geometry>
        <box size="0.1 0.5 0.03 "/>
      </geometry>
    </collision>
  </link>
  <link name="leg_BL">
    <inertial>
      <origin rpy="0.0 0.0 0.0" xyz="0.0 0.0 0.0"/>
      <mass value="0.0"/>
      <inertia ixx="0.0" ixy="0.0" ixz="0.0" iyy="0.0" iyz="0.0" izz="0.0"/>
    </inertial>
    <visual name="">
      <origin rpy="1.5707963267948966 0 0" xyz="0 0 -0.2"/>
      <geometry>
        <box size="0.1 0.5 0.03 "/>
      </geometry>
      <material name="">
        <color rgba="1.0 0.0 1.0 1.0"/>
        <texture filename=""/>
        <texture filename=""/>
      </material>
    </visual>
    <collision>
      <origin rpy="0.0 0.0 0.0" xyz="0.0 0.0 0.0"/>
      <geometry>
        <box size="0.1 0.5 0.03 "/>
      </geometry>
    </collision>
  </link>
  <!-- joints  -->
  <!-- front right limb -->
  <joint name="thigh_FR_joint" type="revolute">
    <origin rpy="0 0.0 0.0" xyz="0.5 0.5 0"/>
    <parent link="base_link"/>
    <child link="thigh_FR"/>
    <axis xyz="0.0 1.0 0.0"/>
    <limit effort="0.1" lower="-1.5707963267948966" upper="1.5707963267948966" velocity="10"/>
  </joint>
  <joint name="leg_FR_joint" type="revolute">
    <origin rpy="0 0.0 0.0" xyz="0 0 -0.4"/>
    <parent link="thigh_FR"/>
    <child link="leg_FR"/>
    <axis xyz="0.0 1.0 0.0"/>
    <limit effort="0.1" lower="-1.5707963267948966" upper="1.5707963267948966" velocity="10"/>
  </joint>
  <!-- back right limb -->
  <joint name="thigh_BR_joint" type="revolute">
    <origin rpy="0 0.0 0.0" xyz="-0.5 0.5 0"/>
    <parent link="base_link"/>
    <child link="thigh_BR"/>
    <axis xyz="0.0 1.0 0.0"/>
    <limit effort="0.1" lower="-1.5707963267948966" upper="1.5707963267948966" velocity="10"/>
  </joint>
  <joint name="leg_BR_joint" type="revolute">
    <origin rpy="0 0.0 0.0" xyz="0 0 -0.4"/>
    <parent link="thigh_BR"/>
    <child link="leg_BR"/>
    <axis xyz="0.0 1.0 0.0"/>
    <limit effort="0.1" lower="-1.5707963267948966" upper="1.5707963267948966" velocity="10"/>
  </joint>
  <!-- front left limb -->
  <joint name="thigh_FL_joint" type="revolute">
    <origin rpy="0 0.0 0.0" xyz="0.5 -0.5 0"/>
    <parent link="base_link"/>
    <child link="thigh_FL"/>
    <axis xyz="0.0 1.0 0.0"/>
    <limit effort="0.1" lower="-1.5707963267948966" upper="1.5707963267948966" velocity="10"/>
  </joint>
  <joint name="leg_FL_joint" type="revolute">
    <origin rpy="0 0.0 0.0" xyz="0 0 -0.4"/>
    <parent link="thigh_FL"/>
    <child link="leg_FL"/>
    <axis xyz="0.0 1.0 0.0"/>
    <limit effort="0.1" lower="-1.5707963267948966" upper="1.5707963267948966" velocity="10"/>
  </joint>
  <!-- back left limb -->
  <joint name="thigh_BL_joint" type="revolute">
    <origin rpy="0 0.0 0.0" xyz="-0.5 -0.5 0"/>
    <parent link="base_link"/>
    <child link="thigh_BL"/>
    <axis xyz="0.0 1.0 0.0"/>
    <limit effort="0.1" lower="-1.5707963267948966" upper="1.5707963267948966" velocity="10"/>
  </joint>
  <joint name="leg_BL_joint" type="revolute">
    <origin rpy="0 0.0 0.0" xyz="0 0 -0.4"/>
    <parent link="thigh_BL"/>
    <child link="leg_BL"/>
    <axis xyz="0.0 1.0 0.0"/>
    <limit effort="0.1" lower="-1.5707963267948966" upper="1.5707963267948966" velocity="10"/>
  </joint>
</robot>
