<?xml version="1.0"?>
<robot xmlns:xacro="http://www.ros.org/wiki/xacro" name="cherry">

<xacro:property name="body_width" value="1.0" />
<xacro:property name="body_len" value="1.5" />
<xacro:property name="body_thickness" value="0.2" />
<xacro:property name="thickness" value="0.03" />
<xacro:property name="leg_len" value="0.5" />
<xacro:property name="hind_len" value="0.5" />
<xacro:property name="limb_width" value="0.1" />
<xacro:property name="joint_vel" value="10" />

<xacro:property name="front_right_limb_x" value="0.5" />
<xacro:property name="front_right_limb_y" value="0.5" />
<xacro:property name="front_right_limb_z" value="-0.2" />

<xacro:property name="front_right_leg_x" value="0" />
<xacro:property name="front_right_leg_y" value="0" />
<xacro:property name="front_right_leg_z" value="-0.4" />
<xacro:property name="front_right_leg_joint_z" value="-0.2" />

<xacro:property name="back_right_limb_x" value="-0.5" />
<xacro:property name="back_right_limb_y" value="0.5" />
<xacro:property name="back_right_limb_z" value="-0.2" />

<xacro:property name="back_right_leg_x" value="0" />
<xacro:property name="back_right_leg_y" value="0" />
<xacro:property name="back_right_leg_z" value="-0.4" />
<xacro:property name="back_right_leg_joint_z" value="-0.2" />


<xacro:property name="front_left_limb_x" value="0.5" />
<xacro:property name="front_left_limb_y" value="-0.5" />
<xacro:property name="front_left_limb_z" value="-0.2" />

<xacro:property name="front_left_leg_x" value="0" />
<xacro:property name="front_left_leg_y" value="0" />
<xacro:property name="front_left_leg_z" value="-0.4" />
<xacro:property name="front_left_leg_joint_z" value="-0.2" />


<xacro:property name="back_left_limb_x" value="-0.5" />
<xacro:property name="back_left_limb_y" value="-0.5" />
<xacro:property name="back_left_limb_z" value="-0.2" />

<xacro:property name="back_left_leg_x" value="0" />
<xacro:property name="back_left_leg_y" value="0" />
<xacro:property name="back_left_leg_z" value="-0.4" />
<xacro:property name="back_left_leg_joint_z" value="-0.2" />



 <link name="base_link">
    <visual>
        <geometry>
           <box size="${body_len} ${body_width} ${body_thickness}"/>
        </geometry>
        <material name="blue"/>
    </visual>
    <collision>
        <geometry>
            <box size="${body_len} ${body_width}  ${body_thickness}"/>
        </geometry>
    </collision>
    <inertial>
        <origin xyz="0.0 0.0 0.0" rpy="0.0 0.0 0.0"/>
        <mass value="0.5"/>
        <geometry>
            <box size="${body_len} ${body_width}  ${body_thickness}"/>
        </geometry>
    </inertial>
    <collision>
        <geometry>
            <box size="${body_len} ${body_width}  ${body_thickness}"/>
        </geometry>
    </collision>
</link>

<!-- front right limb -->
<link name="thigh_FR">
    <inertial>
        <origin xyz="0 0 ${front_right_limb_z}" rpy="${pi/2} 0 0 "/>
        <mass value="0.1"/>
        <geometry>
            <box size="${body_len} ${body_width}  ${body_thickness}"/>
        </geometry>
    </inertial>
    <visual name="">
        <origin xyz="0 0 ${front_right_limb_z}" rpy="${pi/2} 0 0 "/>
        <geometry>
            <box size="${limb_width} ${leg_len} ${thickness} "/>
        </geometry>
        <material name="">
            <color rgba="1.0 0.0 0.0 1.0"/>
            <texture filename=""/>
            <texture filename=""/>
        </material>
    </visual>
    <collision>
        <origin xyz="0.0 0.0 0.0" rpy="0.0 0.0 0.0"/>
        <geometry>
            <box size="${limb_width} ${leg_len} ${thickness} "/>
            
        </geometry>
    </collision>
</link>

<link name="leg_FR">
    <inertial>
        <origin xyz="0.0 0.0 0.0" rpy="0.0 0.0 0.0"/>
        <mass value="0.0"/>
        <inertia ixx="0.0" ixy="0.0" ixz="0.0" iyy="0.0" iyz="0.0" izz="0.0"/>
    </inertial>
    <visual name="">
        <origin xyz="0 0 ${front_right_leg_joint_z}" rpy="${pi/2} 0 0"/>
        <geometry>
            <box size="${limb_width} ${leg_len} ${thickness} "/>
        </geometry>
        <material name="">
            <color rgba="1.0 0.0 1.0 1.0"/>
            <texture filename=""/>
            <texture filename=""/>
        </material>
    </visual>
    <collision>
        <origin xyz="0.0 0.0 0.0" rpy="0.0 0.0 0.0"/>
        <geometry>
            <box size="${limb_width} ${leg_len} ${thickness} "/>
            
        </geometry>
    </collision>
</link>

<!-- front right limb -->
<link name="thigh_BR">
    <inertial>
        <origin xyz="0.0 0.0 0.0" rpy="0.0 0.0 0.0"/>
        <mass value="0.0"/>
        <inertia ixx="0.0" ixy="0.0" ixz="0.0" iyy="0.0" iyz="0.0" izz="0.0"/>
    </inertial>
    <visual name="">
        <origin xyz="0 0 ${back_right_limb_z}" rpy="${pi/2} 0 0 "/>
        <geometry>
            <box size="${limb_width} ${leg_len} ${thickness} "/>
        </geometry>
        <material name="">
            <color rgba="1.0 0.0 0.0 1.0"/>
            <texture filename=""/>
            <texture filename=""/>
        </material>
    </visual>
    <collision>
        <origin xyz="0.0 0.0 0.0" rpy="0.0 0.0 0.0"/>
        <geometry>
            <box size="${limb_width} ${leg_len} ${thickness} "/>
            
        </geometry>
    </collision>
</link>

<link name="leg_BR">
    <inertial>
        <origin xyz="0.0 0.0 0.0" rpy="0.0 0.0 0.0"/>
        <mass value="0.0"/>
        <inertia ixx="0.0" ixy="0.0" ixz="0.0" iyy="0.0" iyz="0.0" izz="0.0"/>
    </inertial>
    <visual name="">
        <origin xyz="0 0 ${back_right_leg_joint_z}" rpy="${pi/2} 0 0"/>
        <geometry>
            <box size="${limb_width} ${leg_len} ${thickness} "/>
        </geometry>
        <material name="">
            <color rgba="1.0 0.0 1.0 1.0"/>
            <texture filename=""/>
            <texture filename=""/>
        </material>
    </visual>
    <collision>
        <origin xyz="0.0 0.0 0.0" rpy="0.0 0.0 0.0"/>
        <geometry>
            <box size="${limb_width} ${leg_len} ${thickness} "/>
            
        </geometry>
    </collision>
</link>



<!-- front left limb -->
<link name="thigh_FL">
    <inertial>
        <origin xyz="0.0 0.0 0.0" rpy="0.0 0.0 0.0"/>
        <mass value="0.0"/>
        <inertia ixx="0.0" ixy="0.0" ixz="0.0" iyy="0.0" iyz="0.0" izz="0.0"/>
    </inertial>
    <visual name="">
        <origin xyz="0 0 ${front_left_limb_z}" rpy="${pi/2} 0 0 "/>
        <geometry>
            <box size="${limb_width} ${leg_len} ${thickness} "/>
        </geometry>
        <material name="">
            <color rgba="1.0 0.0 0.0 1.0"/>
            <texture filename=""/>
            <texture filename=""/>
        </material>
    </visual>
    <collision>
        <origin xyz="0.0 0.0 0.0" rpy="0.0 0.0 0.0"/>
        <geometry>
            <box size="${limb_width} ${leg_len} ${thickness} "/>
            
        </geometry>
    </collision>
</link>

<link name="leg_FL">
    <inertial>
        <origin xyz="0.0 0.0 0.0" rpy="0.0 0.0 0.0"/>
        <mass value="0.0"/>
        <inertia ixx="0.0" ixy="0.0" ixz="0.0" iyy="0.0" iyz="0.0" izz="0.0"/>
    </inertial>
    <visual name="">
        <origin xyz="0 0 ${front_left_leg_joint_z}" rpy="${pi/2} 0 0"/>
        <geometry>
            <box size="${limb_width} ${leg_len} ${thickness} "/>
        </geometry>
        <material name="">
            <color rgba="1.0 0.0 1.0 1.0"/>
            <texture filename=""/>
            <texture filename=""/>
        </material>
    </visual>
    <collision>
        <origin xyz="0.0 0.0 0.0" rpy="0.0 0.0 0.0"/>
        <geometry>
            <box size="${limb_width} ${leg_len} ${thickness} "/>
            
        </geometry>
    </collision>
</link>


<!-- back left limb -->
<link name="thigh_BL">
    <inertial>
        <origin xyz="0.0 0.0 0.0" rpy="0.0 0.0 0.0"/>
        <mass value="0.0"/>
        <inertia ixx="0.0" ixy="0.0" ixz="0.0" iyy="0.0" iyz="0.0" izz="0.0"/>
    </inertial>
    <visual name="">
        <origin xyz="0 0 ${back_left_limb_z}" rpy="${pi/2} 0 0 "/>
        <geometry>
            <box size="${limb_width} ${leg_len} ${thickness} "/>
        </geometry>
        <material name="">
            <color rgba="1.0 0.0 0.0 1.0"/>
            <texture filename=""/>
            <texture filename=""/>
        </material>
    </visual>
    <collision>
        <origin xyz="0.0 0.0 0.0" rpy="0.0 0.0 0.0"/>
        <geometry>
            <box size="${limb_width} ${leg_len} ${thickness} "/>
            
        </geometry>
    </collision>
</link>

<link name="leg_BL">
    <inertial>
        <origin xyz="0.0 0.0 0.0" rpy="0.0 0.0 0.0"/>
        <mass value="0.0"/>
        <inertia ixx="0.0" ixy="0.0" ixz="0.0" iyy="0.0" iyz="0.0" izz="0.0"/>
    </inertial>
    <visual name="">
        <origin xyz="0 0 ${back_left_leg_joint_z}" rpy="${pi/2} 0 0"/>
        <geometry>
            <box size="${limb_width} ${leg_len} ${thickness} "/>
        </geometry>
        <material name="">
            <color rgba="1.0 0.0 1.0 1.0"/>
            <texture filename=""/>
            <texture filename=""/>
        </material>
    </visual>
    <collision>
        <origin xyz="0.0 0.0 0.0" rpy="0.0 0.0 0.0"/>
        <geometry>
            <box size="${limb_width} ${leg_len} ${thickness} "/>
            
        </geometry>
    </collision>
</link>


<!-- joints  -->

<!-- front right limb -->
<joint name="thigh_FR_joint" type="revolute">
    <origin xyz="${front_right_limb_x} ${front_right_limb_y} 0" rpy="0 0.0 0.0"/>
    <parent link="base_link"/>
    <child link="thigh_FR"/>
    <axis xyz="0.0 1.0 0.0"/>
    <limit lower="-${pi/2}" upper="${pi/2}" effort="0.1" velocity="${joint_vel}"/>
</joint>

<joint name="leg_FR_joint" type="revolute">
    <origin xyz="${front_right_leg_x} ${front_right_leg_y} ${front_right_leg_z}" rpy="0 0.0 0.0"/>
    <parent link="thigh_FR"/>
    <child link="leg_FR"/>
    <axis xyz="0.0 1.0 0.0"/>
    <limit lower="-${pi/2}" upper="${pi/2}" effort="0.1" velocity="${joint_vel}"/>
</joint>

<!-- back right limb -->
<joint name="thigh_BR_joint" type="revolute">
    <origin xyz="${back_right_limb_x} ${back_right_limb_y} 0" rpy="0 0.0 0.0"/>
    <parent link="base_link"/>
    <child link="thigh_BR"/>
    <axis xyz="0.0 1.0 0.0"/>
    <limit lower="-${pi/2}" upper="${pi/2}" effort="0.1" velocity="${joint_vel}"/>
</joint>

<joint name="leg_BR_joint" type="revolute">
    <origin xyz="${back_right_leg_x} ${back_right_leg_y} ${back_right_leg_z}" rpy="0 0.0 0.0"/>
    <parent link="thigh_BR"/>
    <child link="leg_BR"/>
    <axis xyz="0.0 1.0 0.0"/>
    <limit lower="-${pi/2}" upper="${pi/2}" effort="0.1" velocity="${joint_vel}"/>
</joint>

<!-- front left limb -->
<joint name="thigh_FL_joint" type="revolute">
    <origin xyz="${front_left_limb_x} ${front_left_limb_y} 0" rpy="0 0.0 0.0"/>
    <parent link="base_link"/>
    <child link="thigh_FL"/>
    <axis xyz="0.0 1.0 0.0"/>
    <limit lower="-${pi/2}" upper="${pi/2}" effort="0.1" velocity="${joint_vel}"/>
</joint>

<joint name="leg_FL_joint" type="revolute">
    <origin xyz="${front_left_leg_x} ${front_left_leg_y} ${front_left_leg_z}" rpy="0 0.0 0.0"/>
    <parent link="thigh_FL"/>
    <child link="leg_FL"/>
    <axis xyz="0.0 1.0 0.0"/>
    <limit lower="-${pi/2}" upper="${pi/2}" effort="0.1" velocity="${joint_vel}"/>
</joint>

<!-- back left limb -->
<joint name="thigh_BL_joint" type="revolute">
    <origin xyz="${back_left_limb_x} ${back_left_limb_y} 0" rpy="0 0.0 0.0"/>
    <parent link="base_link"/>
    <child link="thigh_BL"/>
    <axis xyz="0.0 1.0 0.0"/>
    <limit lower="-${pi/2}" upper="${pi/2}" effort="0.1" velocity="${joint_vel}"/>
</joint>

<joint name="leg_BL_joint" type="revolute">
    <origin xyz="${back_left_leg_x} ${back_left_leg_y} ${back_left_leg_z}" rpy="0 0.0 0.0"/>
    <parent link="thigh_BL"/>
    <child link="leg_BL"/>
    <axis xyz="0.0 1.0 0.0"/>
    <limit lower="-${pi/2}" upper="${pi/2}" effort="0.1" velocity="${joint_vel}"/>
</joint>

</robot>